<html>
<head><meta charset="utf-8"><title>Login - Internal Server Error · production help · Zulip Chat Archive</title></head>
<h2>Stream: <a href="https://rht.github.io/czo-archive/stream/31-production-help/index.html">production help</a></h2>
<h3>Topic: <a href="https://rht.github.io/czo-archive/stream/31-production-help/topic/Login.20-.20Internal.20Server.20Error.html">Login - Internal Server Error</a></h3>

<hr>

<base href="https://chat.zulip.org">

<head><link href="https://rht.github.io/czo-archive/style.css" rel="stylesheet"></head>

<a name="570911"></a>
<h4><a href="https://chat.zulip.org#narrow/stream/31-production%20help/topic/Login%20-%20Internal%20Server%20Error/near/570911" class="zl"><img src="https://rht.github.io/czo-archive/assets/img/zulip.svg" alt="view this post on Zulip" style="width:20px;height:20px;"></a> Swapneel <a href="https://rht.github.io/czo-archive/stream/31-production-help/topic/Login.20-.20Internal.20Server.20Error.html#570911">(Apr 27 2018 at 06:01)</a>:</h4>
<p>We've installed 1.8.0 successfully. Upon accessing the URL for login, we see an 'Internal Server Error'  and the following error in the server.log</p>
<div class="codehilite"><pre><span></span>2018-04-27 05:48:29.447 ERR  [django.request] Internal Server Error: /
Traceback (most recent call last):
  File &quot;/home/zulip/deployments/2018-04-25-21-06-28/zulip-py3-venv/lib/python3.5/site-packages/django/core/handlers/exception.py&quot;, line 41, in inner
    response = get_response(request)
  File &quot;/home/zulip/deployments/2018-04-25-21-06-28/zulip-py3-venv/lib/python3.5/site-packages/django/core/handlers/base.py&quot;, line 187, in _get_response
    response = self.process_exception_by_middleware(e, request)
  File &quot;/home/zulip/deployments/2018-04-25-21-06-28/zulip-py3-venv/lib/python3.5/site-packages/django/core/handlers/base.py&quot;, line 185, in _get_response
    response = wrapped_callback(request, *callback_args, **callback_kwargs)
  File &quot;./zerver/views/home.py&quot;, line 83, in home
    return home_real(request)
  File &quot;./zerver/decorator.py&quot;, line 370, in _wrapped_view
    return view_func(request, *args, **kwargs)
  File &quot;./zerver/decorator.py&quot;, line 415, in _wrapped_view_func
    return rate_limit()(view_func)(request, *args, **kwargs)
  File &quot;./zerver/decorator.py&quot;, line 747, in wrapped_func
    return func(request, *args, **kwargs)
  File &quot;./zerver/views/home.py&quot;, line 124, in home_real
    narrow=narrow)
  File &quot;./zerver/lib/events.py&quot;, line 637, in do_events_register
    narrow=narrow)
  File &quot;./zerver/tornado/event_queue.py&quot;, line 582, in request_event_queue
    resp.raise_for_status()
  File &quot;/home/zulip/deployments/2018-04-25-21-06-28/zulip-py3-venv/lib/python3.5/site-packages/requests/models.py&quot;, line 935, in raise_for_status
    raise HTTPError(http_error_msg, response=self)
requests.exceptions.HTTPError: 401 Client Error: Unauthorized for url: http://127.0.0.1:9993/api/v1/events?lifespan_secs=0&amp;narrow=%5B%5D&amp;client_gravatar=true&amp;apply_markdown=true&amp;all_public_streams=false&amp;client=internal&amp;dont_block=true&amp;user_client=website
&#39;&#39;&#39;
</pre></div>


<p>Any help would be much appreciated. Thank you.</p>



<a name="570972"></a>
<h4><a href="https://chat.zulip.org#narrow/stream/31-production%20help/topic/Login%20-%20Internal%20Server%20Error/near/570972" class="zl"><img src="https://rht.github.io/czo-archive/assets/img/zulip.svg" alt="view this post on Zulip" style="width:20px;height:20px;"></a> Tim Abbott <a href="https://rht.github.io/czo-archive/stream/31-production-help/topic/Login.20-.20Internal.20Server.20Error.html#570972">(Apr 27 2018 at 15:20)</a>:</h4>
<p><span class="user-mention" data-user-id="7757">@Swapneel</span> interesting; is there another exception above that one?</p>



<a name="570973"></a>
<h4><a href="https://chat.zulip.org#narrow/stream/31-production%20help/topic/Login%20-%20Internal%20Server%20Error/near/570973" class="zl"><img src="https://rht.github.io/czo-archive/assets/img/zulip.svg" alt="view this post on Zulip" style="width:20px;height:20px;"></a> Tim Abbott <a href="https://rht.github.io/czo-archive/stream/31-production-help/topic/Login.20-.20Internal.20Server.20Error.html#570973">(Apr 27 2018 at 15:21)</a>:</h4>
<p>I've never seen that before, but I'd guess that doing <code>scripts/setup/flush-memcached</code> and then scripts/setup/restart-server` would fix it, since the issue appears to be a mismatch between different processes about your configuration.</p>



<a name="1439293"></a>
<h4><a href="https://chat.zulip.org#narrow/stream/31-production%20help/topic/Login%20-%20Internal%20Server%20Error/near/1439293" class="zl"><img src="https://rht.github.io/czo-archive/assets/img/zulip.svg" alt="view this post on Zulip" style="width:20px;height:20px;"></a> Dmitry Lutts <a href="https://rht.github.io/czo-archive/stream/31-production-help/topic/Login.20-.20Internal.20Server.20Error.html#1439293">(Sep 22 2022 at 11:56)</a>:</h4>
<p>Hello!<br>
I have a problem. About a month ago, some employees lost the opportunity to log in to zulip. When trying to log into zalip, they have "500" error. The problem is not local, because under their users can no longer log in on any device, but under other users on devices, authorization is successful.</p>



<a name="1439323"></a>
<h4><a href="https://chat.zulip.org#narrow/stream/31-production%20help/topic/Login%20-%20Internal%20Server%20Error/near/1439323" class="zl"><img src="https://rht.github.io/czo-archive/assets/img/zulip.svg" alt="view this post on Zulip" style="width:20px;height:20px;"></a> Matt <a href="https://rht.github.io/czo-archive/stream/31-production-help/topic/Login.20-.20Internal.20Server.20Error.html#1439323">(Sep 22 2022 at 14:47)</a>:</h4>
<p><span class="user-mention" data-user-id="24812">@Dmitry Lutts</span> is this a self-hosted Zulip or Zulip Cloud? If Zulip Cloud you could email <a href="mailto:support@zulip.com">support@zulip.com</a> with your organization name for better service. If it's self-hosted, perhaps take a look at the <a href="https://zulip.readthedocs.io/en/latest/production/troubleshooting.html">Troubleshooting page</a>, specifically the first few paragraphs that talk about logs and where to look for problems.</p>



<hr><p>Last updated: Oct 02 2023 at 04:38 UTC</p>
</html>