[
    {
        "content": "<p>I am getting lots of email notifications since the latest zulip upgrade. They all point to a single problem which is at postgresql level<br>\n\"OperationalError<br>\nserver closed the connection unexpectedly<br>\n    This probably means the server terminated abnormally<br>\n    before or while processing the request.\"<br>\nIs there some tuning we need to do. I am not seeing any distress log statements in postgres logs</p>",
        "id": 1651091,
        "sender_full_name": "Pankaj Lal",
        "timestamp": 1696149879
    },
    {
        "content": "<p><span class=\"user-mention\" data-user-id=\"16885\">@Pankaj Lal</span> that is not a tuning issue -- it sounds like your postgres server was restarted, which happens when you upgrade it. </p>\n<p>If you restart postgres and don't restart Zulip at the same time, you will get that error once per Zulip Python process (can be ~20) over time as each of those processes next attempt to access the database.</p>",
        "id": 1651263,
        "sender_full_name": "Tim Abbott",
        "timestamp": 1696192727
    },
    {
        "content": "<p><a href=\"https://zulip.readthedocs.io/en/latest/production/troubleshooting.html#restrict-unattended-upgrades\">https://zulip.readthedocs.io/en/latest/production/troubleshooting.html#restrict-unattended-upgrades</a> talks about this if you're curious to learn more.</p>",
        "id": 1651264,
        "sender_full_name": "Tim Abbott",
        "timestamp": 1696192771
    }
]