[
    {
        "content": "<p>I got this error when installing, from latest git:</p>\n<div class=\"codehilite\"><pre><span></span>./manage.py checkconfig\nTraceback (most recent call last):\n  File &quot;./manage.py&quot;, line 36, in &lt;module&gt;\n    execute_from_command_line(sys.argv)\n  File &quot;/home/zulip/deployments/2018-08-04-20-00-00/zulip-py3-venv/lib/python3.6/site-packages/django/core/management/__init__.py&quot;, line 364, in execute_from_command_line\n    utility.execute()\n  File &quot;/home/zulip/deployments/2018-08-04-20-00-00/zulip-py3-venv/lib/python3.6/site-packages/django/core/management/__init__.py&quot;, line 356, in execute\n    self.fetch_command(subcommand).run_from_argv(self.argv)\n  File &quot;/home/zulip/deployments/2018-08-04-20-00-00/zulip-py3-venv/lib/python3.6/site-packages/django/core/management/base.py&quot;, line 283, in run_from_argv\n    self.execute(*args, **cmd_options)\n  File &quot;/home/zulip/deployments/2018-08-04-20-00-00/zulip-py3-venv/lib/python3.6/site-packages/django/core/management/base.py&quot;, line 327, in execute\n    self.check()\n  File &quot;/home/zulip/deployments/2018-08-04-20-00-00/zulip-py3-venv/lib/python3.6/site-packages/django/core/management/base.py&quot;, line 359, in check\n    include_deployment_checks=include_deployment_checks,\n  File &quot;/home/zulip/deployments/2018-08-04-20-00-00/zulip-py3-venv/lib/python3.6/site-packages/django/core/management/base.py&quot;, line 346, in _run_checks\n    return checks.run_checks(**kwargs)\n  File &quot;/home/zulip/deployments/2018-08-04-20-00-00/zulip-py3-venv/lib/python3.6/site-packages/django/core/checks/registry.py&quot;, line 81, in run_checks\n    new_errors = check(app_configs=app_configs)\n  File &quot;/home/zulip/deployments/2018-08-04-20-00-00/zulip-py3-venv/lib/python3.6/site-packages/django/core/checks/urls.py&quot;, line 16, in check_url_config\n    return check_resolver(resolver)\n  File &quot;/home/zulip/deployments/2018-08-04-20-00-00/zulip-py3-venv/lib/python3.6/site-packages/django/core/checks/urls.py&quot;, line 26, in check_resolver\n    return check_method()\n  File &quot;/home/zulip/deployments/2018-08-04-20-00-00/zulip-py3-venv/lib/python3.6/site-packages/django/urls/resolvers.py&quot;, line 254, in check\n    for pattern in self.url_patterns:\n  File &quot;/home/zulip/deployments/2018-08-04-20-00-00/zulip-py3-venv/lib/python3.6/site-packages/django/utils/functional.py&quot;, line 35, in __get__\n    res = instance.__dict__[self.name] = self.func(instance)\n  File &quot;/home/zulip/deployments/2018-08-04-20-00-00/zulip-py3-venv/lib/python3.6/site-packages/django/urls/resolvers.py&quot;, line 405, in url_patterns\n    patterns = getattr(self.urlconf_module, &quot;urlpatterns&quot;, self.urlconf_module)\n  File &quot;/home/zulip/deployments/2018-08-04-20-00-00/zulip-py3-venv/lib/python3.6/site-packages/django/utils/functional.py&quot;, line 35, in __get__\n    res = instance.__dict__[self.name] = self.func(instance)\n  File &quot;/home/zulip/deployments/2018-08-04-20-00-00/zulip-py3-venv/lib/python3.6/site-packages/django/urls/resolvers.py&quot;, line 398, in urlconf_module\n    return import_module(self.urlconf_name)\n  File &quot;/usr/lib/python3.6/importlib/__init__.py&quot;, line 126, in import_module\n    return _bootstrap._gcd_import(name[level:], package, level)\n  File &quot;&lt;frozen importlib._bootstrap&gt;&quot;, line 994, in _gcd_import\n  File &quot;&lt;frozen importlib._bootstrap&gt;&quot;, line 971, in _find_and_load\n  File &quot;&lt;frozen importlib._bootstrap&gt;&quot;, line 955, in _find_and_load_unlocked\n  File &quot;&lt;frozen importlib._bootstrap&gt;&quot;, line 665, in _load_unlocked\n  File &quot;&lt;frozen importlib._bootstrap_external&gt;&quot;, line 678, in exec_module\n  File &quot;&lt;frozen importlib._bootstrap&gt;&quot;, line 219, in _call_with_frames_removed\n  File &quot;/home/zulip/deployments/2018-08-04-20-00-00/zproject/urls.py&quot;, line 8, in &lt;module&gt;\n    import zerver.forms\n  File &quot;/home/zulip/deployments/2018-08-04-20-00-00/zerver/forms.py&quot;, line 20, in &lt;module&gt;\n    from zerver.lib.actions import do_change_password, email_not_system_bot, \\\n  File &quot;/home/zulip/deployments/2018-08-04-20-00-00/zerver/lib/actions.py&quot;, line 18, in &lt;module&gt;\n    from zerver.lib.bugdown import (\n  File &quot;/home/zulip/deployments/2018-08-04-20-00-00/zerver/lib/bugdown/__init__.py&quot;, line 35, in &lt;module&gt;\n    from zerver.lib.emoji import translate_emoticons, emoticon_regex\n  File &quot;/home/zulip/deployments/2018-08-04-20-00-00/zerver/lib/emoji.py&quot;, line 19, in &lt;module&gt;\n    with open(NAME_TO_CODEPOINT_PATH) as fp:\nFileNotFoundError: [Errno 2] No such file or directory: &#39;/home/zulip/prod-static/generated/emoji/name_to_codepoint.json&#39;\nzulip@zulip2:~/deployments/2018-08-04-20-00-00$ ls -l /home/zulip/prod-static/generated/emoji/name_to_codepoint.json\nls: cannot access &#39;/home/zulip/prod-static/generated/emoji/name_to_codepoint.json&#39;: No such file or directory\n</pre></div>\n\n\n<p>I searched on the system and found name_to_codepoint.json in <code>/srv/zulip-emoji-cache/24c3428ae5f5f3c84e9ebb2cad8eb79be7454116/emoji/name_to_codepoint.json</code>, so I just copied that whole dir:</p>\n<div class=\"codehilite\"><pre><span></span>cp -a /srv/zulip-emoji-cache/24c3428ae5f5f3c84e9ebb2cad8eb79be7454116/emoji/ /home/zulip/prod-static/generated/\n</pre></div>\n\n\n<p>and that seemed to fix the problem...</p>",
        "id": 625761,
        "sender_full_name": "Laurence Darby",
        "timestamp": 1533410311
    },
    {
        "content": "<p><span class=\"user-mention\" data-user-id=\"7\">@Tim Abbott</span>  is this something you think should be resolved before release?</p>",
        "id": 625762,
        "sender_full_name": "Laurence Darby",
        "timestamp": 1533410351
    },
    {
        "content": "<p>Hmm, definitely a bug in that it should have been generated in the install process.  Don't have time to look right now; <span class=\"user-mention\" data-user-id=\"907\">@Harshit Bansal</span> may be able to help investigate.</p>",
        "id": 625768,
        "sender_full_name": "Tim Abbott",
        "timestamp": 1533411098
    },
    {
        "content": "<p>I'm also getting <code>open() \"/home/zulip/prod-static/html/5xx.html\" failed</code> now.  There was nothing in /home/zulip/prod-static/ apart from generated/bots .  I'll check over the installer console output and see if there was maybe some error that didn't abort it.</p>\n<p>edit to clairfy: I meant that /home/zulip/prod-static/generated/bots already existed.  Creating /home/zulip/prod-static/generated/emoji fixed the ./manage.py checkconfig errror, but then trying to access the new organisation page gave the error <code>open() \"/home/zulip/prod-static/html/5xx.html\" failed</code> in the nginx logs.</p>",
        "id": 625770,
        "sender_full_name": "Laurence Darby",
        "timestamp": 1533411926
    },
    {
        "content": "<p>Figured out part of the issue, there was this error earlier:</p>\n<div class=\"codehilite\"><pre><span></span>+ su zulip -c &#39;/home/zulip/deployments/current/tools/update-prod-static --authors-not-required&#39;\n+ mkdir -p var/log\nCached version not found! Installing node modules.\n+ mkdir -p /srv/zulip-npm-cache/8ea4cd291dd23441aec0f298b77b6ddc0d0a7a56\n+ cp package.json yarn.lock /srv/zulip-npm-cache/8ea4cd291dd23441aec0f298b77b6ddc0d0a7a56\n+ /home/zulip/deployments/current/scripts/lib/cd_exec /srv/zulip-npm-cache/8ea4cd291dd23441aec0f298b77b6ddc0d0a7a56 /srv/zulip-yarn/bin/yarn install --non-interactive --prod\n+ touch /srv/zulip-npm-cache/8ea4cd291dd23441aec0f298b77b6ddc0d0a7a56/.success-stamp\nUsing cached node modules from /srv/zulip-npm-cache/8ea4cd291dd23441aec0f298b77b6ddc0d0a7a56/node_modules\n+ rm -rf node_modules\n+ ln -nsf /srv/zulip-npm-cache/8ea4cd291dd23441aec0f298b77b6ddc0d0a7a56/node_modules node_modules\n+ ./tools/setup/emoji/build_emoji\n+ ./tools/inline-email-css\n+ ./tools/setup/generate_zulip_bots_static_files\n+ ./tools/generate-custom-icon-webfont\n+ ./tools/setup/build_pygments_data\n+ ./tools/minify-js\n\nError running a subcommand of /home/zulip/deployments/current/tools/update-prod-static: ./tools/minify-js\nActual error output for the subcommand is just above this.\n</pre></div>\n\n\n<p>This created /home/zulip/prod-static/generated, but didn't complete it, but then the install script skips update-prod-static if generated exists.</p>",
        "id": 625776,
        "sender_full_name": "Laurence Darby",
        "timestamp": 1533413666
    },
    {
        "content": "<p>running ./tools/minify-js manually gives this:</p>\n<div class=\"codehilite\"><pre><span></span>ERROR - Cannot read: static/node_modules/katex/dist/katex.js\n</pre></div>",
        "id": 625778,
        "sender_full_name": "Laurence Darby",
        "timestamp": 1533413857
    },
    {
        "content": "<div class=\"codehilite\"><pre><span></span>root@zulip2:~/zulip# cd static/\nroot@zulip2:~/zulip/static# ln -s ../node_modules/\nroot@zulip2:~/zulip/static# cd ..\n</pre></div>\n\n\n<p>fixed that issue.</p>",
        "id": 625782,
        "sender_full_name": "Laurence Darby",
        "timestamp": 1533414941
    },
    {
        "content": "<p>And finally the update-prod-static command worked, and created everything in /home/zulip/prod-static/generated/,  and the install script was successful.  So, a few things to fix here:</p>\n<ul>\n<li>if update-prod-static fails then need to delete the generated dir, so it's re-attempted</li>\n<li>if ./tools/minify-js fails, the error isn't printed unless it's run manually</li>\n<li>finally the node_modules path, /home/zulip/deployments/current/node_modules exists but not /home/zulip/deployments/current/static/node_modules  (was something supposed to create static/node_modules that failed?  I did the same trick again of just finding the files it was looking for and putting them in place, the first time with the emojis that was wrong and didn't actually help).</li>\n</ul>",
        "id": 625786,
        "sender_full_name": "Laurence Darby",
        "timestamp": 1533415652
    },
    {
        "content": "<p>Hmm, yeah, these must be recent regressions.  I'll try reproducing probably tomorrow.</p>",
        "id": 625792,
        "sender_full_name": "Tim Abbott",
        "timestamp": 1533416996
    },
    {
        "content": "<p>sorry, <span class=\"user-mention\" data-user-id=\"7\">@Tim Abbott</span>  the ../node_modules/ is already there, nothing to fix really (although maybe the first 2 issues could still be improved...)</p>\n<p>I had done <code>scp -r ./zulip zulip-server:~/ </code> which deleted the symlink.  Incredibly annoying!</p>",
        "id": 625805,
        "sender_full_name": "Laurence Darby",
        "timestamp": 1533424923
    },
    {
        "content": "<p><span class=\"user-mention\" data-user-id=\"9089\">@Laurence Darby</span> just wanted to follow-up; I was unable to reproduce any issues with running the installer; it sounds like the root cause was that you copied the contents in a way that didn't preserve symlinks after unpacking it?</p>",
        "id": 627614,
        "sender_full_name": "Tim Abbott",
        "timestamp": 1533756903
    },
    {
        "content": "<p>If so, it's possible we should just add a check early in the installer for whether certain symlinks are present, and if not, throw an error?</p>",
        "id": 627615,
        "sender_full_name": "Tim Abbott",
        "timestamp": 1533756927
    },
    {
        "content": "<p><span class=\"user-mention\" data-user-id=\"7\">@Tim Abbott</span>  yes that was the issue, got it all working now.  So yes checking the symlink exists would make sense, thanks. </p>\n<p>Also, after doing all that I realised I'd need to migrate the data from the old 1604 install one to the new, and jump postgres versions, then read <a href=\"https://zulip.readthedocs.io/en/latest/production/export-and-import.html\" target=\"_blank\" title=\"https://zulip.readthedocs.io/en/latest/production/export-and-import.html\">https://zulip.readthedocs.io/en/latest/production/export-and-import.html</a>,  which says it has to be the same version...  </p>\n<p>So I needed to get the old one upgraded anyway - I fixed the rabbitmq errors by doing this:</p>\n<div class=\"codehilite\"><pre><span></span>apt-get purge rabbitmq-server\napt-get install rabbitmq-server\n..../scripts/setup/configure-rabbitmq\n</pre></div>\n\n\n<p>then apt could stop and start it properly, then the zulip upgrade to git worked (so trying 1804 at all was a waste of time...)</p>",
        "id": 627708,
        "sender_full_name": "Laurence Darby",
        "timestamp": 1533760879
    },
    {
        "content": "<p><span class=\"user-mention\" data-user-id=\"9089\">@Laurence Darby</span> cool, congrats on the upgrade, and thanks for the feedback!</p>",
        "id": 627710,
        "sender_full_name": "Tim Abbott",
        "timestamp": 1533760991
    }
]