[
    {
        "content": "<p>Upon entering my e-mail and password to register a new Zulip organization I get an internal error page show up. This is what I find in <code>/var/log/zulip/errors.log</code></p>\n<div class=\"codehilite\"><pre><span></span>2018-08-31 10:54:33.287 ERR  [django.request] Internal Server Error: /accounts/register/\nTraceback (most recent call last):\n  File &quot;/home/zulip/deployments/2018-08-30-13-08-33/zulip-py3-venv/lib/python3.5/site-packages/django/core/handlers/exception.py&quot;, line 41, in inner\n    response = get_response(request)\n  File &quot;/home/zulip/deployments/2018-08-30-13-08-33/zulip-py3-venv/lib/python3.5/site-packages/django/core/handlers/base.py&quot;, line 187, in _get_response\n    response = self.process_exception_by_middleware(e, request)\n  File &quot;/home/zulip/deployments/2018-08-30-13-08-33/zulip-py3-venv/lib/python3.5/site-packages/django/core/handlers/base.py&quot;, line 185, in _get_response\n    response = wrapped_callback(request, *callback_args, **callback_kwargs)\n  File &quot;./zerver/decorator.py&quot;, line 127, in wrapper\n    return func(request, *args, **kwargs)\n  File &quot;./zerver/views/registration.py&quot;, line 149, in accounts_register\n    ldap_attrs = _LDAPUser(backend, ldap_username).attrs\n  File &quot;/home/zulip/deployments/2018-08-30-13-08-33/zulip-py3-venv/lib/python3.5/site-packages/django_auth_ldap/backend.py&quot;, line 461, in attrs\n    self._load_user_attrs()\n  File &quot;/home/zulip/deployments/2018-08-30-13-08-33/zulip-py3-venv/lib/python3.5/site-packages/django_auth_ldap/backend.py&quot;, line 500, in _load_user_attrs\n    if self.dn is not None:\n  File &quot;/home/zulip/deployments/2018-08-30-13-08-33/zulip-py3-venv/lib/python3.5/site-packages/django_auth_ldap/backend.py&quot;, line 454, in dn\n    self._load_user_dn()\n  File &quot;/home/zulip/deployments/2018-08-30-13-08-33/zulip-py3-venv/lib/python3.5/site-packages/django_auth_ldap/backend.py&quot;, line 527, in _load_user_dn\n    self._user_dn = self._search_for_user_dn()\n  File &quot;/home/zulip/deployments/2018-08-30-13-08-33/zulip-py3-venv/lib/python3.5/site-packages/django_auth_ldap/backend.py&quot;, line 549, in _search_for_user_dn\n    results = search.execute(self.connection, {&#39;user&#39;: self._username})\n  File &quot;/home/zulip/deployments/2018-08-30-13-08-33/zulip-py3-venv/lib/python3.5/site-packages/django_auth_ldap/backend.py&quot;, line 476, in connection\n    self._bind()\n  File &quot;/home/zulip/deployments/2018-08-30-13-08-33/zulip-py3-venv/lib/python3.5/site-packages/django_auth_ldap/backend.py&quot;, line 804, in _bind\n    sticky=True)\n  File &quot;/home/zulip/deployments/2018-08-30-13-08-33/zulip-py3-venv/lib/python3.5/site-packages/django_auth_ldap/backend.py&quot;, line 815, in _bind_as\n    self._get_connection().simple_bind_s(force_text(bind_dn),\n  File &quot;/home/zulip/deployments/2018-08-30-13-08-33/zulip-py3-venv/lib/python3.5/site-packages/django_auth_ldap/backend.py&quot;, line 829, in _get_connection\n    self._connection = self.backend.ldap.initialize(uri, bytes_mode=False)\n  File &quot;/home/zulip/deployments/2018-08-30-13-08-33/zulip-py3-venv/lib/python3.5/site-packages/ldap/functions.py&quot;, line 85, in initialize\n    return LDAPObject(uri,trace_level,trace_file,trace_stack_limit,bytes_mode)\n  File &quot;/home/zulip/deployments/2018-08-30-13-08-33/zulip-py3-venv/lib/python3.5/site-packages/ldap/ldapobject.py&quot;, line 104, in __init__\n    self._l = ldap.functions._ldap_function_call(ldap._ldap_module_lock,_ldap.initialize,uri)\n  File &quot;/home/zulip/deployments/2018-08-30-13-08-33/zulip-py3-venv/lib/python3.5/site-packages/ldap/functions.py&quot;, line 55, in _ldap_function_call\n    result = func(*args,**kwargs)\nldap.LDAPError: (0, &#39;Error&#39;)\n</pre></div>\n\n\n<p>I can't copy the actual values but I set up AUTH_LDAP_BIND_DN, AUTH_LDAP_SERVER_URI, AUTH_LDAP_USER_SEARCH, LDAP_APPEND_DOMAIN and LDAP_EMAIL_ATTR</p>",
        "id": 640437,
        "sender_full_name": "Peter Nagy",
        "timestamp": 1535713375
    },
    {
        "content": "<p>I just found in the prod settings template one can check ldap via <code>./manage.py query_ldap</code>, this returns the same error. The problem is from the <code>(0, 'Error')</code> it's hard to tell whether the issue is on my side or not.</p>",
        "id": 640439,
        "sender_full_name": "Peter Nagy",
        "timestamp": 1535713652
    },
    {
        "content": "<p>did you also set the <code>auth_ldap_bind_password</code> in the <code>/etc/zulip/zulip-secrets.conf</code> file?</p>",
        "id": 640484,
        "sender_full_name": "Scott Russell",
        "timestamp": 1535724574
    },
    {
        "content": "<p>yes. I suspect this to be a non-zulip issue for now as I can't connect to our ldap server any other way. I don't know ldap well though so my attempts are at best crude</p>",
        "id": 640485,
        "sender_full_name": "Peter Nagy",
        "timestamp": 1535724663
    },
    {
        "content": "<p>There are three options:</p>\n<p>1. For connectivity tests to non-SSL ports just try to use <code>telnet &lt;hostname&gt; &lt;port&gt;</code> and make sure you get a connection.<br>\n2. For connectivity tests to SSL ports, use <code>openssl s_client -connect &lt;host&gt;:&lt;port&gt;</code>. Also use this to verify that all your certificates are correctly set both on the client and the server<br>\n3. If connectivity and SSL certs all look good from the above commands, then test with the <code>ldapsearch</code> CLI. It's part of the <em>ldap-utils</em> package. Examples of using ldapsearch are online.</p>",
        "id": 640496,
        "sender_full_name": "Scott Russell",
        "timestamp": 1535727931
    },
    {
        "content": "<p>Once you get to step 3 above, you should know all the needed settings to put into your zulip settings.py file and you can again test with manage.py query_ldap again.</p>",
        "id": 640497,
        "sender_full_name": "Scott Russell",
        "timestamp": 1535728009
    },
    {
        "content": "<p>Good luck!</p>",
        "id": 640498,
        "sender_full_name": "Scott Russell",
        "timestamp": 1535728024
    },
    {
        "content": "<p>I managed to get this working. First I got help from network management to get a successful <code>ldapsearch</code> command and then I mapped the values to the ldap parameters in <code>settings.py</code>.</p>\n<p>What I still don't get is the search term. There's <code>LDAP_EMAIL_ATTR</code> which would suggest one can use a non-email username to authenticate against ldap but after an unsuccessful login the error message says</p>\n<div class=\"codehilite\"><pre><span></span>Please enter a correct email and password. Note that both fields may be case-sensitive.\n</pre></div>\n\n\n<p>So how does one use a non-email username for ldap?</p>\n<p>Another thing that could be explained or linked to some docs is the magical <code>%(user)s</code> value in the search term.</p>",
        "id": 641389,
        "sender_full_name": "Peter Nagy",
        "timestamp": 1536145315
    },
    {
        "content": "<p>It our AD we usually login with thr attribute <code>uid</code> and the user email is stored in the <code>mail</code> attribute.</p>\n<p>So in our search filter we would use <code>uid=%(user)s</code> and set the value of LDAP_EMAIL_ATTR to be <code>mail</code>.</p>",
        "id": 641436,
        "sender_full_name": "Scott Russell",
        "timestamp": 1536159590
    },
    {
        "content": "<p><span class=\"user-mention\" data-user-id=\"5233\">@Scott Russell</span> and what do you use as the username to log in? The name or the e-mail?</p>",
        "id": 641645,
        "sender_full_name": "Peter Nagy",
        "timestamp": 1536215832
    },
    {
        "content": "<p><span class=\"user-mention\" data-user-id=\"9021\">@Peter Nagy</span> whatever the value of UID is in LDAP becomes the login name.</p>",
        "id": 641658,
        "sender_full_name": "Scott Russell",
        "timestamp": 1536239836
    },
    {
        "content": "<p>what's up with the error message above then? It's strictly asking for email and password</p>",
        "id": 641659,
        "sender_full_name": "Peter Nagy",
        "timestamp": 1536239873
    },
    {
        "content": "<p>When you got that message did you by chance have another backend besides LDAP also enabled? Like the default email and password backend?</p>",
        "id": 641695,
        "sender_full_name": "Scott Russell",
        "timestamp": 1536252054
    },
    {
        "content": "<p><span class=\"user-mention\" data-user-id=\"5233\">@Scott Russell</span> no, I set up LDAP as the only authentication backend</p>",
        "id": 641899,
        "sender_full_name": "Peter Nagy",
        "timestamp": 1536303142
    },
    {
        "content": "<p><span class=\"user-mention\" data-user-id=\"9021\">@Peter Nagy</span> I'm at a loss then to explain what you saw. Zulip would only ask for an email login if</p>\n<p>1. A backend that used email addresses was enabled and configured. (eg LDAP_EMAIL_ATTR  not set or some other backend also enabled in addition to LDAP)<br>\n2. Changed settings but did not restart Zulip services<br>\n3. Sunspots and my general ignorance of zulip internals.</p>",
        "id": 641919,
        "sender_full_name": "Scott Russell",
        "timestamp": 1536333035
    },
    {
        "content": "<p>There's 3 models for how to configure ldap</p>",
        "id": 642024,
        "sender_full_name": "Tim Abbott",
        "timestamp": 1536352675
    }
]