[
    {
        "content": "<p>Greetings, I'm using SAML (Keycloak) for user authentication.<br>\nSo far I've setup the auth and am also forwarded to the idp, but on redirect to zulip I'm find myself on the sso login page again.</p>\n<p>The auth.log says the following:<br>\n<code>2020-11-02 10:57:52.360 INFO [zulip.auth.saml] /complete/saml/: No valid IdP as issuer of the SAMLResponse.</code><br>\nBut Keycloak says it authenticated me successful.</p>\n<p>I was forced by Keycloak to provide a \"Valid Redirect URI\" but don't know what to put there, so I used<br>\n<code>https://zulip.dm.cap.pink/complete/saml/</code><br>\nIf no URI provided the authentication fails.</p>\n<p>The config I used in settings.py is in the following pastebin<br>\n<a href=\"https://paste.debian.net/hidden/b2b88957/\">https://paste.debian.net/hidden/b2b88957/</a></p>\n<p>Do you have an idea what I did wrong?<br>\nThank you for your attention.</p>",
        "id": 1054267,
        "sender_full_name": "cap",
        "timestamp": 1604321246
    },
    {
        "content": "<p><span class=\"user-mention\" data-user-id=\"17716\">@cap</span> Like  in <a href=\"#narrow/stream/31-production-help/topic/SAML.3A.20Issuer.20of.20the.20Assertion.20not.20found.20or.20multiple/near/1040963\">https://chat.zulip.org/#narrow/stream/31-production-help/topic/SAML.3A.20Issuer.20of.20the.20Assertion.20not.20found.20or.20multiple/near/1040963</a> in your case I would also recommend manually investgating the SAMLResponse for any irregularities (and the declared Issuers ) so that we can see if that can be causing the error</p>",
        "id": 1054718,
        "sender_full_name": "Mateusz Mandera",
        "timestamp": 1604348163
    }
]