[
    {
        "content": "<p>I've got another odd user registration problem...</p>\n<h2>Steps</h2>\n<ul>\n<li>user sent an invite</li>\n<li>clicked on invite</li>\n<li>tried to login via username + password (which don't exist yet)<ul>\n<li>normal / expected method is login via Google SSO (works fine for most others)</li>\n</ul>\n</li>\n<li>now, Zulip won't load at all with the following error in the browser terminal:</li>\n</ul>\n<div class=\"codehilite\"><pre><span></span><code>Unknown user_id in get_by_user_id: 152\nUncaught TypeError: Cannot read properties of undefined (reading &#39;date_joined&#39;)\n</code></pre></div>",
        "id": 1370663,
        "sender_full_name": "James VL",
        "timestamp": 1650472212
    },
    {
        "content": "<p>The user no longer shows up under \"Users\" or \"Deactivated Users\" and I cannot resend the invite because it says they already exist in the system.</p>",
        "id": 1370666,
        "sender_full_name": "James VL",
        "timestamp": 1650472496
    },
    {
        "content": "<p><span class=\"user-mention\" data-user-id=\"19765\">@James VL</span> I'd check the server logs -- it seems likely an exception was thrown while creating the user.</p>",
        "id": 1370701,
        "sender_full_name": "Tim Abbott",
        "timestamp": 1650475063
    },
    {
        "content": "<p>And what that exception is will determine how to correct the situation, which seems pretty clearly a case of the user only being half-created (or something).</p>",
        "id": 1370702,
        "sender_full_name": "Tim Abbott",
        "timestamp": 1650475086
    },
    {
        "content": "<p>The only error in my logs from yesterday (when this happened) is</p>\n<div class=\"codehilite\"><pre><span></span><code>2022-04-19 19:57:48.637 ERR  [zerver.middleware.json_error_handler] Traceback (most recent call last):\n  File &quot;/srv/zulip-venv-cache/726c7d1d35d9cd61bb4b70e98167a1db7b0c524d/zulip-py3-venv/lib/python3.8/site-packages/django/core/handlers/base.py&quot;, line 181, in _get_response\n    response = wrapped_callback(request, *callback_args, **callback_kwargs)\n  File &quot;/home/zulip/deployments/2022-04-05-19-49-42/./zerver/lib/rest.py&quot;, line 33, in _wrapped_view_func\n    response = view_func(request, *args, **kwargs)\n  File &quot;/srv/zulip-venv-cache/726c7d1d35d9cd61bb4b70e98167a1db7b0c524d/zulip-py3-venv/lib/python3.8/site-packages/django/views/decorators/csrf.py&quot;, line 54, in wrapped_view\n    return view_func(*args, **kwargs)\n  File &quot;/home/zulip/deployments/2022-04-05-19-49-42/./zerver/lib/rest.py&quot;, line 169, in rest_dispatch\n    return target_function(request, **kwargs)\n  File &quot;/srv/zulip-venv-cache/726c7d1d35d9cd61bb4b70e98167a1db7b0c524d/zulip-py3-venv/lib/python3.8/site-packages/django/utils/decorators.py&quot;, line 130, in _wrapped_view\n    response = view_func(request, *args, **kwargs)\n  File &quot;/home/zulip/deployments/2022-04-05-19-49-42/./zerver/decorator.py&quot;, line 790, in _wrapped_view_func\n    return authenticate_log_and_execute_json(\n  File &quot;/home/zulip/deployments/2022-04-05-19-49-42/./zerver/decorator.py&quot;, line 777, in authenticate_log_and_execute_json\n    return limited_view_func(request, user_profile, *args, **kwargs)\n  File &quot;/home/zulip/deployments/2022-04-05-19-49-42/./zerver/decorator.py&quot;, line 984, in wrapped_func\n    return func(request, *args, **kwargs)\n  File &quot;/home/zulip/deployments/2022-04-05-19-49-42/./zerver/decorator.py&quot;, line 599, in _wrapped_view_func\n    return view_func(request, user_profile, *args, **kwargs)\n  File &quot;/home/zulip/deployments/2022-04-05-19-49-42/./zerver/views/invite.py&quot;, line 102, in get_user_invites\n    all_users = do_get_invites_controlled_by_user(user_profile)\n  File &quot;/home/zulip/deployments/2022-04-05-19-49-42/./zerver/lib/actions.py&quot;, line 7828, in do_get_invites_controlled_by_user\n    expiry_date=get_invitation_expiry_date(invitee.confirmation.get()),\n  File &quot;/srv/zulip-venv-cache/726c7d1d35d9cd61bb4b70e98167a1db7b0c524d/zulip-py3-venv/lib/python3.8/site-packages/django/db/models/manager.py&quot;, line 85, in manager_method\n    return getattr(self.get_queryset(), name)(*args, **kwargs)\n  File &quot;/srv/zulip-venv-cache/726c7d1d35d9cd61bb4b70e98167a1db7b0c524d/zulip-py3-venv/lib/python3.8/site-packages/django/db/models/query.py&quot;, line 435, in get\n    raise self.model.DoesNotExist(\nconfirmation.models.Confirmation.DoesNotExist: Confirmation matching query does not exist.\n\n2022-04-19 19:57:48.708 ERR  [django.request] Internal Server Error: /json/invites\n2022-04-20 14:08:27.961 WARN [django.security.csrf:9800] Forbidden (CSRF token missing or incorrect.): /json/events\n</code></pre></div>",
        "id": 1370716,
        "sender_full_name": "James VL",
        "timestamp": 1650475842
    },
    {
        "content": "<p>But that may have been triggered when they tried to use the same e-mail invite again after logging in w/out a password didn't work</p>",
        "id": 1370719,
        "sender_full_name": "James VL",
        "timestamp": 1650475862
    },
    {
        "content": "<p>Hmm, this traceback looks like <a href=\"https://github.com/zulip/zulip/issues/21691\">https://github.com/zulip/zulip/issues/21691</a> I think - and it's from an attempt to fetch invites, rather than a user sign in attempt</p>",
        "id": 1371348,
        "sender_full_name": "Mateusz Mandera",
        "timestamp": 1650569071
    },
    {
        "content": "<blockquote>\n<p>The only error in my logs from yesterday (when this happened) is</p>\n</blockquote>\n<p>Are there any different errors from earlier? Perhaps the user registered earlier than the day of the error reported at the top of this thread?</p>",
        "id": 1371354,
        "sender_full_name": "Mateusz Mandera",
        "timestamp": 1650569161
    },
    {
        "content": "<p>I don't think that would have been possible - I created the invite myself. I think he did try to register / create his own account after the invite was sent though.</p>",
        "id": 1373258,
        "sender_full_name": "James VL",
        "timestamp": 1650922839
    },
    {
        "content": "<p>I finally used the zulip management commands to change the email address of the originally invited user to a dummy address, and then re-sent the invite - it worked when he used the email link.</p>",
        "id": 1373260,
        "sender_full_name": "James VL",
        "timestamp": 1650922926
    }
]