[
    {
        "content": "<p>We saw regular django 47 memcached errors on our zulip 2.1 (debian 10) installation and expected them to disappear after updating to latest zulip 2.1.7. We upgraded saturday, and today it happened again:</p>\n<div class=\"codehilite\"><pre><span></span><code>Error generated by Anonymous user (not logged in) on zulip deployment\n\nTraceback (most recent call last):\n  File &quot;/srv/zulip-venv-cache/6176a52fab8737c09656fc8ad0352547e9801c07/zulip-py3-venv/lib/python3.7/site-packages/django/contrib/sessions/backends/base.py&quot;, line 202, in _get_session\n    return self._session_cache\nAttributeError: &#39;SessionStore&#39; object has no attribute &#39;_session_cache&#39;\n\nDuring handling of the above exception, another exception occurred:\n\nTraceback (most recent call last):\n  File &quot;/srv/zulip-venv-cache/6176a52fab8737c09656fc8ad0352547e9801c07/zulip-py3-venv/lib/python3.7/site-packages/django_pylibmc/memcached.py&quot;, line 130, in get\n    return super(PyLibMCCache, self).get(key, default, version)\n  File &quot;/srv/zulip-venv-cache/6176a52fab8737c09656fc8ad0352547e9801c07/zulip-py3-venv/lib/python3.7/site-packages/django/core/cache/backends/memcached.py&quot;, line 79, in get\n    val = self._cache.get(key)\npylibmc.Error: error 31 from memcached_get(:1:django.contrib.sessions.cache): (0x561a972d8bf0) A TIMEOUT OCCURRED, No active_fd were found,  host: 127.0.0.1:11211 -&gt; libmemcached/io.cc:259\n\nDuring handling of the above exception, another exception occurred:\n\nTraceback (most recent call last):\n  File &quot;/srv/zulip-venv-cache/6176a52fab8737c09656fc8ad0352547e9801c07/zulip-py3-venv/lib/python3.7/site-packages/django_pylibmc/memcached.py&quot;, line 140, in set\n    **COMPRESS_KWARGS)\npylibmc.ServerDown: error 47 from memcached_set: (0x561a972d8bf0) SERVER HAS FAILED AND IS DISABLED UNTIL TIMED RETRY,  host: 127.0.0.1:11211 -&gt; libmemcached/connect.cc:720\n\n\nDeployed code:\n- ZULIP_VERSION: 2.1.7\n- version: 2.1.7\n</code></pre></div>\n\n\n<p>There are always only two notifications in a row, and usually it happens only once a day, around a whole hour (sample times: 5:56 PM, 8:57 AM, 9:00 AM) but there are also days that they don't show up. The zulip system itself seems to work fine.</p>\n<p>Is there something specific to our installation (it's a very regular install, using the regular procedure from »  Zulip in Production » Production Installation)</p>\n<p>Are we the only ones still seeing this in 2.1.7?</p>",
        "id": 918231,
        "sender_full_name": "mouk",
        "timestamp": 1593416323
    },
    {
        "content": "<p><span class=\"user-mention\" data-user-id=\"16223\">@mouk</span> I'm getting these since upgrading from 2.1.4-0 to 2.1.7-0 a couple of days ago. I get these errors every couple of minutes.</p>",
        "id": 918233,
        "sender_full_name": "Felix Fontein",
        "timestamp": 1593417158
    },
    {
        "content": "<p>(I'm using the docker deploy. Also a regular install.)</p>",
        "id": 918234,
        "sender_full_name": "Felix Fontein",
        "timestamp": 1593417193
    },
    {
        "content": "<p>Every couple of minutes. That's different. And your installation is also working fine?</p>",
        "id": 918235,
        "sender_full_name": "mouk",
        "timestamp": 1593417346
    },
    {
        "content": "<p>It seems to be. At least I didn't notice anything that's not working yet.</p>",
        "id": 918236,
        "sender_full_name": "Felix Fontein",
        "timestamp": 1593417509
    },
    {
        "content": "<p>In my case, the problem might have been that I had to adjust memcached (since the default username changed): <a href=\"https://github.com/zulip/zulip/pull/15462\">https://github.com/zulip/zulip/pull/15462</a></p>",
        "id": 918237,
        "sender_full_name": "Felix Fontein",
        "timestamp": 1593417805
    },
    {
        "content": "<p>Your error message is different in some details though, so this probably a different error.</p>",
        "id": 918238,
        "sender_full_name": "Felix Fontein",
        "timestamp": 1593417920
    },
    {
        "content": "<p>Sorry for missing the difference when comparing the errors...</p>",
        "id": 918239,
        "sender_full_name": "Felix Fontein",
        "timestamp": 1593417958
    },
    {
        "content": "<p>But are you saying you actually changed the username in settings.py? With me it's the default (so I guess  this changed to \"zulip@localhost\" since 2.1.7)</p>",
        "id": 918240,
        "sender_full_name": "mouk",
        "timestamp": 1593418072
    },
    {
        "content": "<p>No, but for the docker setup, the username is explicitly set for memcached itself (not for zulip), and that needed to be updated to what zulip is now using.</p>",
        "id": 918241,
        "sender_full_name": "Felix Fontein",
        "timestamp": 1593418190
    },
    {
        "content": "<p>right, thanks.</p>",
        "id": 918242,
        "sender_full_name": "mouk",
        "timestamp": 1593418314
    },
    {
        "content": "<p><span class=\"user-mention\" data-user-id=\"16386\">@Felix Fontein</span> just to check, was the issue that you needed to update your <code>docker-compose.yml</code> for changes we made in the 2.1.7 release of <code>docker-zulip</code>, or do you think there are issues with our current <code>docker-compose.yml</code>?</p>",
        "id": 918576,
        "sender_full_name": "Tim Abbott",
        "timestamp": 1593455943
    },
    {
        "content": "<p><span class=\"user-mention\" data-user-id=\"7\">@Tim Abbott</span> thanks for checking! This issue was because I converted the docker-compose.yml to an Ansible script (to avoid using docker-compose), and I didn't first check whether the docker-compose.yml in <a href=\"https://github.com/zulip/docker-zulip/\">https://github.com/zulip/docker-zulip/</a> changed.</p>",
        "id": 918797,
        "sender_full_name": "Felix Fontein",
        "timestamp": 1593459977
    },
    {
        "content": "<p>OK, great, good to know!</p>",
        "id": 918799,
        "sender_full_name": "Tim Abbott",
        "timestamp": 1593460006
    },
    {
        "content": "<p>I upgraded from 2.1.3 to 2.1.7 (Dockerhub doesn't have a 3.0 image as for now) and now I'm bombarded with these memcached error 47 emails. Got 1000+ mails within one day. <span aria-label=\"sad\" class=\"emoji emoji-2639\" role=\"img\" title=\"sad\">:sad:</span> </p>\n<p>What did I do?</p>\n<ul>\n<li>Upgrade Docker-Zulip to 2.1.7</li>\n<li>Added the one line to docker-compose.yml that was introduced with 2.1.7:</li>\n</ul>\n<div class=\"codehilite\"><pre><span></span><code>echo &quot;zulip@localhost::$$MEMCACHED_PASSWORD&quot; &gt;&gt; &quot;$$MEMCACHED_SASL_PWDB&quot;\n</code></pre></div>\n\n\n<ul>\n<li>Restarted the stack.</li>\n</ul>\n<p>That's all. Zulip works fine, but the flood of emails keeps coming in.</p>\n<p>In the meantime, my hosting provider rebooted the VS. Don't know if that's an issue.</p>\n<p>Is there anything I can do?</p>\n<p>I can only use Zulip with Docker since I'm bound to an OpenVZ VS where a normal installation won't run.</p>\n<p>Any hint appreciated!</p>\n<div class=\"codehilite\"><pre><span></span><code>version: &#39;2&#39;\nservices:\n  database:\n    image: &#39;zulip/zulip-postgresql:10&#39;\n    environment:\n      POSTGRES_DB: &#39;zulip&#39;\n      POSTGRES_USER: &#39;zulip&#39;\n      # Note that you need to do a manual `ALTER ROLE` query if you\n      # change this on a system after booting the postgres container\n      # the first time on a host.  Instructions are available in README.md.\n      POSTGRES_PASSWORD: &#39;******obscured******&#39;\n    volumes:\n      - &#39;/opt/docker/zulip/postgresql/data:/var/lib/postgresql/data:rw&#39;\n    restart: always\n  memcached:\n    image: &#39;memcached:alpine&#39;\n    command:\n      - &#39;sh&#39;\n      - &#39;-euc&#39;\n      - |\n        echo &#39;mech_list: plain&#39; &gt; &quot;$$SASL_CONF_PATH&quot;\n        echo &quot;zulip@$$HOSTNAME:$$MEMCACHED_PASSWORD&quot; &gt; &quot;$$MEMCACHED_SASL_PWDB&quot;\n        echo &quot;zulip@localhost::$$MEMCACHED_PASSWORD&quot; &gt;&gt; &quot;$$MEMCACHED_SASL_PWDB&quot;\n        exec memcached -S\n    environment:\n      SASL_CONF_PATH: &#39;/home/memcache/memcached.conf&#39;\n      MEMCACHED_SASL_PWDB: &#39;/home/memcache/memcached-sasl-db&#39;\n      MEMCACHED_PASSWORD: &#39;******obscured******&#39;\n    restart: always\n  rabbitmq:\n    image: &#39;rabbitmq:3.7.7&#39;\n    hostname: zulip-rabbit\n    restart: always\n    environment:\n        RABBITMQ_DEFAULT_USER: &#39;zulip&#39;\n        RABBITMQ_DEFAULT_PASS: &#39;******obscured******&#39;\n    volumes:\n      - &#39;/opt/docker/zulip/rabbitmq:/var/lib/rabbitmq:rw&#39;\n  redis:\n    image: &#39;redis:alpine&#39;\n    command:\n      - &#39;sh&#39;\n      - &#39;-euc&#39;\n      - |\n        echo &quot;requirepass &#39;$$REDIS_PASSWORD&#39;&quot; &gt; /etc/redis.conf\n        exec redis-server /etc/redis.conf\n    environment:\n      REDIS_PASSWORD: &#39;******obscured******&#39;\n    volumes:\n      - &#39;/opt/docker/zulip/redis:/data:rw&#39;\n    restart: always\n  zulip:\n    image: &#39;zulip/docker-zulip:2.1.7-0&#39;\n#    build:\n#      context: .\n#      args:\n        # Change these if you want to build zulip from a different repo/branch\n#        ZULIP_GIT_URL: https://github.com/zulip/zulip.git\n#        ZULIP_GIT_REF: 2.1.7\n        # Set this up if you plan to use your own CA certificate bundle for building\n        # CUSTOM_CA_CERTIFICATES:\n    ports:\n      - &#39;10080:80&#39;\n      - &#39;10443:443&#39;\n#    expose:\n#      - 443\n    environment:\n      DB_HOST: &#39;database&#39;\n      DB_HOST_PORT: &#39;5432&#39;\n      DB_USER: &#39;zulip&#39;\n      SSL_CERTIFICATE_GENERATION: &#39;self-signed&#39;\n      SETTING_MEMCACHED_LOCATION: &#39;memcached:11211&#39;\n      SETTING_RABBITMQ_HOST: &#39;rabbitmq&#39;\n      SETTING_REDIS_HOST: &#39;redis&#39;\n      SECRETS_email_password: &#39;******obscured******&#39;\n      # These should match RABBITMQ_DEFAULT_PASS, POSTGRES_PASSWORD,\n      # MEMCACHED_PASSWORD, and REDIS_PASSWORD above.\n      SECRETS_rabbitmq_password: &#39;******obscured******&#39;\n      SECRETS_postgres_password: &#39;******obscured******&#39;\n      SECRETS_memcached_password: &#39;******obscured******&#39;\n      SECRETS_redis_password: &#39;******obscured******&#39;\n      SECRETS_secret_key: &#39;******obscured******&#39;\n      SETTING_EXTERNAL_HOST: &#39;******obscured******&#39;\n      SETTING_ZULIP_ADMINISTRATOR: &#39;******obscured******&#39;\n      SETTING_EMAIL_HOST: &#39;******obscured******&#39;  # e.g. smtp.example.com\n      SETTING_EMAIL_HOST_USER: &#39;******obscured******&#39;\n      SETTING_EMAIL_PORT: &#39;25&#39;\n      # It seems that the email server needs to use ssl or tls and can&#39;t be used without it\n      SETTING_EMAIL_USE_SSL: &#39;False&#39;\n      SETTING_EMAIL_USE_TLS: &#39;True&#39;\n      ZULIP_AUTH_BACKENDS: &#39;EmailAuthBackend&#39;\n      SETTING_USE_X_FORWARDED_HOST: &#39;True&#39;\n      SETTING_ALLOWED_HOSTS: &quot;[&#39;*&#39;, &#39;0.0.0.0&#39;]&quot;\n      DISABLE_HTTPS: &quot;True&quot;\n\n      # Settings for custom Terms and Privacy Policy\n      SETTING_TERMS_OF_SERVICE: &#39;/data/terms.md&#39;\n      SETTING_PRIVACY_POLICY: &#39;/data/privacy.md&#39;\n\n      # Settings für Incoming E-Mail (Polling)\n      SETTING_EMAIL_GATEWAY_PATTERN: &quot;******obscured******&quot;\n      SETTING_EMAIL_GATEWAY_LOGIN: &quot;******obscured******&quot;\n      SETTING_EMAIL_GATEWAY_IMAP_SERVER: &quot;******obscured******&quot;\n      SETTING_EMAIL_GATEWAY_IMAP_PORT: &quot;******obscured******&quot;\n      SETTING_EMAIL_GATEWAY_IMAP_FOLDER: &quot;INBOX&quot;\n      SECRETS_email_gateway_password: &quot;******obscured******&quot;\n\n      # Settings für JITSI\n      SETTING_JITSI_SERVER_URL: &quot;******obscured******&quot;\n\n      # Uncomment this when configuring the mobile push notifications service\n      SETTING_PUSH_NOTIFICATION_BOUNCER_URL: &#39;https://push.zulipchat.com&#39;\n    volumes:\n      - &#39;/opt/docker/zulip/zulip:/data:rw&#39;\n    ulimits:\n      nofile:\n        soft: 40000\n        hard: 50000\n    restart: unless-stopped\n</code></pre></div>",
        "id": 943018,
        "sender_full_name": "Roman Bannack",
        "timestamp": 1595026212
    },
    {
        "content": "<p><span class=\"user-mention\" data-user-id=\"14475\">@Roman Bannack</span> the issue is almost certainly that memcached authentication is broken.</p>",
        "id": 943097,
        "sender_full_name": "Tim Abbott",
        "timestamp": 1595033470
    },
    {
        "content": "<p>In theory this change is what you needed to do, but I see you have that:<br>\n<a href=\"https://github.com/zulip/docker-zulip/commit/0810e2ba67ddf34f59f619cb07c60a40c08de235\">https://github.com/zulip/docker-zulip/commit/0810e2ba67ddf34f59f619cb07c60a40c08de235</a></p>",
        "id": 943098,
        "sender_full_name": "Tim Abbott",
        "timestamp": 1595033489
    },
    {
        "content": "<p>But I guess I'd recommend double-checking that you have the same credentials used for memcached authentication in all places.</p>",
        "id": 943099,
        "sender_full_name": "Tim Abbott",
        "timestamp": 1595033532
    },
    {
        "content": "<p>(An unfortunate aspect of memcached specifically being broken is that its exceptions have a random value in them that avoids our rate-limiting of a given exception)</p>",
        "id": 943100,
        "sender_full_name": "Tim Abbott",
        "timestamp": 1595033557
    },
    {
        "content": "<p><span class=\"user-mention\" data-user-id=\"7\">@Tim Abbott</span> What I noticed is that the error is reported for some other deployment than \"current\":</p>\n<div class=\"codehilite\"><pre><span></span><code>Logger django.pylibmc, from module django_pylibmc.memcached line 146:\nError generated by Anonymous user (not logged in) on 37b2d2122a11 deployment\n\nTraceback (most recent call last):\n  File &quot;/home/zulip/deployments/2020-06-26-05-15-05/zulip-py3-venv/lib/python3.6/site-packages/django/contrib/sessions/backends/base.py&quot;, line 202, in _get_session\n    return self._session_cache\nAttributeError: &#39;SessionStore&#39; object has no attribute &#39;_session_cache&#39;\n(...)\nDeployed code:\n- ZULIP_VERSION: 2.1.7\n- version: docker\n</code></pre></div>\n\n\n<p>2020-06-26 is obviously not the date that I upgraded to 2.1.7. Don't know if that's a hint where the problem is.</p>",
        "id": 943312,
        "sender_full_name": "Roman Bannack",
        "timestamp": 1595072879
    },
    {
        "content": "<p>Other than that, credentials are the same everywhere as passed from <code>docker-compose.yml</code>.</p>",
        "id": 943314,
        "sender_full_name": "Roman Bannack",
        "timestamp": 1595072997
    },
    {
        "content": "<p>There are two different error emails sent, more or less interchanging: <a href=\"https://pastebin.com/WAteb4n2\">one</a> and <a href=\"https://pastebin.com/hceEaCvb\">two</a>. Both say \"error 47 from memcached_set (...)\" in the subject.</p>",
        "id": 943317,
        "sender_full_name": "Roman Bannack",
        "timestamp": 1595073555
    },
    {
        "content": "<p><span class=\"user-mention\" data-user-id=\"699\">@Anders Kaseorg</span> do we have a memcached debugging guide?  Maybe we should write one so we can point folks at it for this sort of thing.  Potentially in <code>docs/production/troubleshooting.md</code>?</p>",
        "id": 944718,
        "sender_full_name": "Tim Abbott",
        "timestamp": 1595217441
    },
    {
        "content": "<p>For the record, just now I found the (my) error in the added <code>zulip@localhost</code>auth line in docker-compose.yml:</p>\n<div class=\"codehilite\"><pre><span></span><code>echo &quot;zulip@localhost::$$MEMCACHED_PASSWORD&quot; &gt;&gt; &quot;$$MEMCACHED_SASL_PWDB&quot;\n</code></pre></div>\n\n\n<p>Why did I put in a double colon there in the first place? <span aria-label=\"cry\" class=\"emoji emoji-1f622\" role=\"img\" title=\"cry\">:cry:</span> It turns out this was responsible for Zulip failing to authenticate at memcached (no surprise, of course). Though I imagine I copied+pasted the line when I was updating the file.</p>\n<p>Anyhow, thanks all for your patience!</p>",
        "id": 945294,
        "sender_full_name": "Roman Bannack",
        "timestamp": 1595270713
    },
    {
        "content": "<p>Great, thanks for the follow-up <span class=\"user-mention\" data-user-id=\"14475\">@Roman Bannack</span>! <span aria-label=\"slight smile\" class=\"emoji emoji-1f642\" role=\"img\" title=\"slight smile\">:slight_smile:</span></p>",
        "id": 945407,
        "sender_full_name": "Tim Abbott",
        "timestamp": 1595281512
    },
    {
        "content": "<p>It's really valuable to learn this sort of mystery was a typo as opposed to some sort of new bug.</p>",
        "id": 945408,
        "sender_full_name": "Tim Abbott",
        "timestamp": 1595281536
    },
    {
        "content": "<p><span class=\"user-mention silent\" data-user-id=\"7\">Tim Abbott</span> <a href=\"#narrow/stream/31-production-help/topic/zulip.202.2E1.2E7.2C.20django.2047.20memcached.20error.20continued/near/944718\">said</a>:</p>\n<blockquote>\n<p><span class=\"user-mention silent\" data-user-id=\"699\">Anders Kaseorg</span> do we have a memcached debugging guide?  Maybe we should write one so we can point folks at it for this sort of thing.  Potentially in <code>docs/production/troubleshooting.md</code>?</p>\n</blockquote>\n<p>Is there a place I can start on debugging this error? I am on 3.0, started getting this error recently, not very often though.</p>",
        "id": 958295,
        "sender_full_name": "guneet narula",
        "timestamp": 1595887758
    }
]